Workbook

Sheet Cerceda_1habeq_ReCiPe
A1: SimaPro 10.3.0.1 | C1: Date: | D1: 46227 | E1: Time: | F1: 0.45830212
A2: Project | B2: Alberto Fraile
A5: Calculation: | B5: Analyze
A6: Results: | B6: Impact assessment
A7: Product: | B7: 1 p Cerceda_1hab-eq (of project Alberto Fraile)
A8: Method: | B8: ReCiPe 2016 Midpoint (H) V1.12 / World (2010) H
A9: Indicator: | B9: Characterization
A10: Skip categories: | B10: Never
A11: Exclude infrastructure processes: | B11: No
A12: Exclude long-term emissions: | B12: No
A13: Sorted on item: | B13: Impact category
A14: Sort order: | B14: Ascending
A16: Impact category | B16: Unit | C16: Total | D16: Cerceda_1hab-eq emisiones directas | E16: Polyacrylamide {GLO}| market for polyacrylamide | Cut-off, U | F16: Electricity, high voltage {ES}| market for electricity, high voltage | Cut-off, U | G16: Wastewater, unpolluted {RoW}| market for wastewater, unpolluted | Cut-off, U | H16: Sewage sludge, dried {RoW}| market for sewage sludge, dried | Cut-off, U | I16: Inert waste {RoW}| market for inert waste | Cut-off, S - Copied from ecoinvent U | J16: Municipal solid waste {ES}| market for municipal solid waste | Cut-off, U | K16: Residues, MSWI, biowaste {GLO}| market for residues, MSWI, biowaste | Cut-off, U | L16: Total w/o wastewater | M16: Normalization
A17: Global warming | B17: kg CO2 eq | C17: 4.2553664 | D17: 0.1285 | E17: 0.035732653 | F17: 0.085710025 | G17: 0.060955505 | H17: 0.0021075383 | I17: 0.00012378894 | J17: 3.9400893 | K17: 0.0021476142 | L17: =SUM(D17:F17, H17:K17) -> 4.1944109 | M17: =L17/'Final normalization scores No I'!$D$4 -> 0.00052493078 | N17: GWP
A18: Stratospheric ozone depletion | B18: kg CFC11 eq | C18: 4.859951e-06 | D18: 2.75e-06 | E18: 5.3539986e-09 | F18: 5.1151e-08 | G18: 1.322e-08 | H18: 6.0525476e-10 | I18: 3.6524756e-11 | J18: 2.039394e-06 | K18: 1.8965345e-10 | L18: =SUM(D18:F18, H18:K18) -> 4.8467304e-06
A19: Ionizing radiation | B19: kBq Co-60 eq | C19: 0.10354748 | D19: 0 | E19: 0.00088414598 | F19: 0.089029376 | G19: 0.0024717377 | H19: 2.1242393e-05 | I19: 1.449994e-06 | J19: 0.011120792 | K19: 1.8735117e-05 | L19: =SUM(D19:F19, H19:K19) -> 0.10107574
A20: Ozone formation, Human health | B20: kg NOx eq | C20: 0.0024904345 | D20: 0 | E20: 6.1416109e-05 | F20: 0.00019374257 | G20: 0.00014862671 | H20: 9.54233e-06 | I20: 6.34327e-07 | J20: 0.0020709401 | K20: 5.532318e-06 | L20: =SUM(D20:F20, H20:K20) -> 0.0023418078
A21: Fine particulate matter formation | B21: kg PM2.5 eq | C21: 0.00079628579 | D21: 0 | E21: 3.8708315e-05 | F21: 7.8984534e-05 | G21: 9.9165646e-05 | H21: 2.455345e-06 | I21: 1.87209e-07 | J21: 0.00057499652 | K21: 1.788221e-06 | L21: =SUM(D21:F21, H21:K21) -> 0.00069712014
A22: Ozone formation, Terrestrial ecosystems | B22: kg NOx eq | C22: 0.0025739192 | D22: 0 | E22: 6.7701071e-05 | F22: 0.00020436855 | G22: 0.0001548981 | H22: 9.975647e-06 | I22: 6.62944e-07 | J22: 0.0021306421 | K22: 5.670728e-06 | L22: =SUM(D22:F22, H22:K22) -> 0.002419021
A23: Terrestrial acidification | B23: kg SO2 eq | C23: 0.0018731383 | D23: 0 | E23: 0.00011960691 | F23: 0.00021888945 | G23: 0.00015279891 | H23: 5.425896e-06 | I23: 4.31915e-07 | J23: 0.0013717435 | K23: 4.241711e-06 | L23: =SUM(D23:F23, H23:K23) -> 0.0017203394
A24: Freshwater eutrophication | B24: kg P eq | C24: 0.0093095957 | D24: 0.00042 | E24: 1.1160084e-05 | F24: 1.4297201e-05 | G24: 4.5410931e-05 | H24: 3.33665e-07 | I24: 5.5971e-08 | J24: 0.0088089556 | K24: 9.382313e-06 | L24: =SUM(D24:F24, H24:K24) -> 0.0092641848 | M24: =L24/'Final normalization scores No I'!$D$23 -> 0.01425504 | N24: FEU
A25: Marine eutrophication | B25: kg N eq | C25: 0.0095480575 | D25: 0.00045738 | E25: 2.2618311e-05 | F25: 2.610577e-06 | G25: 5.306228e-06 | H25: 3.9394e-08 | I25: 2.6025018e-09 | J25: 0.0090600679 | K25: 3.2486e-08 | L25: =SUM(D25:F25, H25:K25) -> 0.0095427513 | M25: =L25/'Final normalization scores No I'!$D$29 -> 0.0020665211 | N25: MEU
A26: Terrestrial ecotoxicity | B26: kg 1,4-DCB | C26: 2.7417645 | D26: 0 | E26: 0.056107079 | F26: 0.10760576 | G26: 0.30250379 | H26: 0.03246358 | I26: 0.002894161 | J26: 2.2367564 | K26: 0.0034336485 | L26: =SUM(D26:F26, H26:K26) -> 2.4392606 | M26: =L26/'Final normalization scores No I'!$D$17 -> 0.00016047439 | N26: TET
A27: Freshwater ecotoxicity | B27: kg 1,4-DCB | C27: 2.5482547 | D27: 0 | E27: 0.0012890596 | F27: 0.0021290029 | G27: 0.0068679662 | H27: 6.0520642e-05 | I27: 5.1579643e-05 | J27: 2.5376126 | K27: 0.00024390998 | L27: =SUM(D27:F27, H27:K27) -> 2.5413867 | M27: =L27/'Final normalization scores No I'!$D$24 -> 0.10095001 | N27: FET
A28: Marine ecotoxicity | B28: kg 1,4-DCB | C28: 3.2385418 | D28: 0 | E28: 0.0016930539 | F28: 0.0028012366 | G28: 0.009189976 | H28: 9.8142884e-05 | I28: 7.4168327e-05 | J28: 3.2243385 | K28: 0.00034675152 | L28: =SUM(D28:F28, H28:K28) -> 3.2293519 | M28: =L28/'Final normalization scores No I'!$D$28 -> 0.074335649 | N28: MET
A29: Human carcinogenic toxicity | B29: kg 1,4-DCB | C29: 0.22758447 | D29: 0 | E29: 0.0049974065 | F29: 0.013238064 | G29: 0.068337009 | H29: 0.00039958094 | I29: 2.690133e-05 | J29: 0.13543571 | K29: 0.0051498066 | L29: =SUM(D29:F29, H29:K29) -> 0.15924747
A30: Human non-carcinogenic toxicity | B30: kg 1,4-DCB | C30: 38.753725 | D30: 0 | E30: 0.031210265 | F30: 0.052878176 | G30: 0.19217377 | H30: 0.0020535819 | I30: 0.0019059872 | J30: 38.439906 | K30: 0.03359652 | L30: =SUM(D30:F30, H30:K30) -> 38.561551 | M30: =L30/'Final normalization scores No I'!$D$10 -> 0.0012338969
A31: Land use | B31: m2a crop eq | C31: 0.022548158 | D31: 0 | E31: 0.00066614549 | F31: 0.0034618832 | G31: 0.00207223 | H31: 0.00013404054 | I31: 9.641863e-06 | J31: 0.016148221 | K31: 5.5995684e-05 | L31: =SUM(D31:F31, H31:K31) -> 0.020475928
A32: Mineral resource scarcity | B32: kg Cu eq | C32: 0.0019359721 | D32: 0 | E32: 9.5653461e-05 | F32: 0.00023600583 | G32: 0.00091315673 | H32: 5.535236e-06 | I32: 3.34749e-07 | J32: 0.00067810435 | K32: 7.181742e-06 | L32: =SUM(D32:F32, H32:K32) -> 0.0010228154
A33: Fossil resource scarcity | B33: kg oil eq | C33: 0.12885246 | D33: 0 | E33: 0.015021349 | F33: 0.026193209 | G33: 0.01494463 | H33: 0.00066682816 | I33: 4.442026e-05 | J33: 0.07168182 | K33: 0.00030020521 | L33: =SUM(D33:F33, H33:K33) -> 0.11390783
A34: Water consumption | B34: m3 | C34: -0.43556278 | D34: 0 | E34: 0.00034531167 | F34: 0.0012318884 | G34: -0.43442118 | H34: 4.547495e-06 | I34: -9.0519251e-06 | J34: -0.002720294 | K34: 5.997837e-06 | L34: =SUM(D34:F34, H34:K34) -> -0.0011416005 | M34: =L34/'Final normalization scores No I'!$D$25 -> -4.281442e-06 | N34: WU
B38: Normalized impacts
B39: =M17 -> 0.00052493078 | C39: GWP
B40: =M24 -> 0.01425504 | C40: FEU
B41: =M25 -> 0.0020665211 | C41: MEU
B42: =M26 -> 0.00016047439 | C42: TET
B43: =M27 -> 0.10095001 | C43: FET
B44: =M28 -> 0.074335649 | C44: MET
B45: =M34 -> -4.281442e-06 | C45: WU

Sheet Cerceda_1kgPO4eq_ReCiPe
A1: SimaPro 10.3.0.1 | C1: Date: | D1: 46227 | E1: Time: | F1: 0.4589609
A2: Project | B2: Alberto Fraile
A5: Calculation: | B5: Analyze
A6: Results: | B6: Impact assessment
A7: Product: | B7: 1 kg Cerceda_1kgPO4-eq (of project Alberto Fraile)
A8: Method: | B8: ReCiPe 2016 Midpoint (H) V1.12 / World (2010) H
A9: Indicator: | B9: Characterization
A10: Skip categories: | B10: Never | G10: No coonsidera Ian
A11: Exclude infrastructure processes: | B11: No
A12: Exclude long-term emissions: | B12: No
A13: Sorted on item: | B13: Impact category | G13: porque ya la habia considerado en emisiones directas | L13: Nueva sumatoria considerada x Ian
A14: Sort order: | B14: Ascending | M14: Con factor
A16: Impact category | B16: Unit | C16: Total | D16: Cerceda_1kgPO4-eq | E16: Polyacrylamide {GLO}| market for polyacrylamide | Cut-off, U | F16: Electricity, high voltage {ES}| market for electricity, high voltage | Cut-off, U | G16: Wastewater, unpolluted {RoW}| market for wastewater, unpolluted | Cut-off, U | H16: Sewage sludge, dried {RoW}| market for sewage sludge, dried | Cut-off, U | I16: Inert waste {RoW}| market for inert waste | Cut-off, S - Copied from ecoinvent U | J16: Municipal solid waste {ES}| market for municipal solid waste | Cut-off, U | K16: Residues, MSWI, biowaste {GLO}| market for residues, MSWI, biowaste | Cut-off, U | L16: Total w/o wastewater | M16: Normalization
A17: Global warming | B17: kg CO2 eq | C17: 506.41389 | D17: 9.806 | E17: 4.2879184 | F17: 10.333265 | G17: 7.3566989 | H17: 0.25486509 | I17: 0.014886012 | J17: 474.10255 | K17: 0.2577137 | L17: =SUM(D17:F17,H17:K17) -> 499.0572 | M17: =L17/'Final normalization scores No I'!$D$4 -> 0.062457038 | N17: GWP
A18: Stratospheric ozone depletion | B18: kg CFC11 eq | C18: 0.00038590117 | D18: 0.000132 | E18: 6.4248e-07 | F18: 6.166831e-06 | G18: 1.59552e-06 | H18: 7.3194e-08 | I18: 4.3922175e-09 | J18: 0.00024539599 | K18: 2.2758e-08 | L18: =SUM(D18:F18,H18:K18) -> 0.00038430565
A19: Ionizing radiation | B19: kBq Co-60 eq | C19: 12.480991 | D19: 0 | E19: 0.10609752 | F19: 10.733448 | G19: 0.29831317 | H19: 0.0025688476 | I19: 0.0001743664 | J19: 1.3381412 | K19: 0.002248214 | L19: =SUM(D19:F19,H19:K19) -> 12.182678
A20: Ozone formation, Human health | B20: kg NOx eq | C20: 0.29975132 | D20: 0 | E20: 0.0073699331 | F20: 0.023357749 | G20: 0.017937706 | H20: 0.0011539562 | I20: 7.6279797e-05 | J20: 0.24919181 | K20: 0.0006638782 | L20: =SUM(D20:F20,H20:K20) -> 0.28181361
A21: Fine particulate matter formation | B21: kg PM2.5 eq | C21: 0.09585783 | D21: 0 | E21: 0.0046449978 | F21: 0.0095224345 | G21: 0.011968268 | H21: 0.00029692539 | I21: 2.2512443e-05 | J21: 0.069188106 | K21: 0.00021458649 | L21: =SUM(D21:F21,H21:K21) -> 0.083889563
A22: Ozone formation, Terrestrial ecosystems | B22: kg NOx eq | C22: 0.30979974 | D22: 0 | E22: 0.0081241285 | F22: 0.024638825 | G22: 0.018694599 | H22: 0.0012063573 | I22: 7.9721085e-05 | J22: 0.25637563 | K22: 0.00068048735 | L22: =SUM(D22:F22,H22:K22) -> 0.29110515
A23: Terrestrial acidification | B23: kg SO2 eq | C23: 0.22545962 | D23: 0 | E23: 0.01435283 | F23: 0.026389475 | G23: 0.018441247 | H23: 0.00065615484 | I23: 5.193919e-05 | J23: 0.16505897 | K23: 0.00050900531 | L23: =SUM(D23:F23,H23:K23) -> 0.20701837
A24: Freshwater eutrophication | B24: kg P eq | C24: 1.1198693 | D24: 0.05019 | E24: 0.0013392101 | F24: 0.0017236812 | G24: 0.0054806296 | H24: 4.0350205e-05 | I24: 6.730718e-06 | J24: 1.0599628 | K24: 0.0011258775 | L24: =SUM(D24:F24,H24:K24) -> 1.1143886 | M24: =L24/'Final normalization scores No I'!$D$23 -> 1.7147386 | N24: FEU
A25: Marine eutrophication | B25: kg N eq | C25: 1.1490782 | D25: 0.05522121 | E25: 0.0027141973 | F25: 0.00031473306 | G25: 0.00064040677 | H25: 4.763922e-06 | I25: 3.12959e-07 | J25: 1.0901787 | K25: 3.898262e-06 | L25: =SUM(D25:F25,H25:K25) -> 1.1484378 | M25: =L25/'Final normalization scores No I'!$D$29 -> 0.24869882 | N25: MEU
A26: Terrestrial ecotoxicity | B26: kg 1,4-DCB | C26: 330.04499 | D26: 0 | E26: 6.7328495 | F26: 12.973031 | G26: 36.509079 | H26: 3.9258283 | I26: 0.34803202 | J26: 269.14414 | K26: 0.41203782 | L26: =SUM(D26:F26,H26:K26) -> 293.53592 | M26: =L26/'Final normalization scores No I'!$D$17 -> 0.019311179 | N26: TET
A27: Freshwater ecotoxicity | B27: kg 1,4-DCB | C27: 306.62856 | D27: 0 | E27: 0.15468715 | F27: 0.25667419 | G27: 0.82889247 | H27: 0.0073187753 | I27: 0.0062026153 | J27: 305.34552 | K27: 0.029269198 | L27: =SUM(D27:F27,H27:K27) -> 305.79967 | M27: =L27/'Final normalization scores No I'!$D$24 -> 12.147101 | N27: FET
A28: Marine ecotoxicity | B28: kg 1,4-DCB | C28: 389.6902 | D28: 0 | E28: 0.20316646 | F28: 0.33771917 | G28: 1.109135 | H28: 0.011868442 | I28: 0.008918976 | J28: 387.97778 | K28: 0.041610183 | L28: =SUM(D28:F28,H28:K28) -> 388.58106 | M28: =L28/'Final normalization scores No I'!$D$28 -> 8.9446511 | N28: MET
A29: Human carcinogenic toxicity | B29: kg 1,4-DCB | C29: 27.409473 | D29: 0 | E29: 0.59968879 | F29: 1.5959909 | G29: 8.2475701 | H29: 0.048321416 | I29: 0.0032349701 | J29: 16.29669 | K29: 0.61797679 | L29: =SUM(D29:F29,H29:K29) -> 19.161903
A30: Human non-carcinogenic toxicity | B30: kg 1,4-DCB | C30: 4663.2148 | D30: 0 | E30: 3.7452317 | F30: 6.3750324 | G30: 23.193386 | H30: 0.24834014 | I30: 0.22920099 | J30: 4625.392 | K30: 4.0315824 | L30: =SUM(D30:F30,H30:K30) -> 4640.0214 | M30: =L30/'Final normalization scores No I'!$D$10 -> 0.14847193
A31: Land use | B31: m2a crop eq | C31: 2.714571 | D31: 0 | E31: 0.079937459 | F31: 0.41736723 | G31: 0.25009672 | H31: 0.016209554 | I31: 0.0011594645 | J31: 1.9430811 | K31: 0.0067194821 | L31: =SUM(D31:F31,H31:K31) -> 2.4644743
A32: Mineral resource scarcity | B32: kg Cu eq | C32: 0.23330632 | D32: 0 | E32: 0.011478415 | F32: 0.02845304 | G32: 0.11020857 | H32: 0.00066937744 | I32: 4.0254589e-05 | J32: 0.081594852 | K32: 0.00086180901 | L32: =SUM(D32:F32,H32:K32) -> 0.12309775
A33: Fossil resource scarcity | B33: kg oil eq | C33: 15.511424 | D33: 0 | E33: 1.8025619 | F33: 3.1578729 | G33: 1.8036622 | H33: 0.080639684 | I33: 0.0053416769 | J33: 8.6253206 | K33: 0.036024625 | L33: =SUM(D33:F33,H33:K33) -> 13.707761
A34: Water consumption | B34: m3 | C34: -52.567334 | D34: 0 | E34: 0.0414374 | F34: 0.14851738 | G34: -52.430142 | H34: 0.00054992959 | I34: -0.0010885226 | J34: -0.32732718 | K34: 0.00071974043 | L34: =SUM(D34:F34,H34:K34) -> -0.13719125 | M34: =L34/'Final normalization scores No I'!$D$25 -> -0.00051452007 | N34: WU
B38: Normalized impacts
B39: =M17 -> 0.062457038 | C39: GWP
B40: =M24 -> 1.7147386 | C40: FEU
B41: =M25 -> 0.24869882 | C41: MEU
B42: =M26 -> 0.019311179 | C42: TET
B43: =M27 -> 12.147101 | C43: FET
B44: =M28 -> 8.9446511 | C44: MET
B45: =M34 -> -0.00051452007 | C45: WU

Sheet Vedra_1habeq_ReCiPe
A1: SimaPro 10.3.0.1 | C1: Date: | D1: 46227 | E1: Time: | F1: 0.45961823
A2: Project | B2: Alberto Fraile
A5: Calculation: | B5: Analyze
A6: Results: | B6: Impact assessment
A7: Product: | B7: 1 p Vedra_1hab-eq (of project Alberto Fraile)
A8: Method: | B8: ReCiPe 2016 Midpoint (H) V1.12 / World (2010) H
A9: Indicator: | B9: Characterization
A10: Skip categories: | B10: Never
A11: Exclude infrastructure processes: | B11: No
A12: Exclude long-term emissions: | B12: No
A13: Sorted on item: | B13: Impact category
A14: Sort order: | B14: Ascending
A16: Impact category | B16: Unit | C16: Total | D16: Vedra_1hab-eq | E16: Polyaluminium chloride {GLO}| market for polyaluminium chloride | Cut-off, U | F16: Methanol {RER}| market for methanol | Cut-off, U | G16: Electricity, medium voltage {ES}| market for electricity, medium voltage | Cut-off, U | H16: Wastewater, unpolluted {RoW}| market for wastewater, unpolluted | Cut-off, U | I16: Sewage sludge, 97% water, WWT-SLF, municipal solid waste {ES}| market for sewage sludge, 97% water, WWT-SLF, municipal solid waste | Cut-off, U | J16: Total w/o wastewater | K16: Normalization
A17: Global warming | B17: kg CO2 eq | C17: 1.284244 | D17: 0.52768 | E17: 0.029497281 | F17: 0.11811811 | G17: 0.47725442 | H17: 0.036433175 | I17: 0.095261042 | J17: =SUM(D17:G17,I17) -> 1.2478109 | K17: =J17/'Final normalization scores No I'!$D$4 -> 0.0001561636 | L17: GWP
A18: Stratospheric ozone depletion | B18: kg CFC11 eq | C18: 5.348666e-06 | D18: 3.96e-06 | E18: 1.203e-08 | F18: 2.4854e-08 | G18: 2.8154e-07 | H18: 7.9016235e-09 | I18: 1.06234e-06 | J18: =SUM(D18:G18,I18) -> 5.340764e-06
A19: Ionizing radiation | B19: kBq Co-60 eq | C19: 0.49231967 | D19: 0 | E19: 0.0014952474 | F19: 0.0034455343 | G19: 0.48553043 | H19: 0.0014773604 | I19: 0.00037110168 | J19: =SUM(D19:G19,I19) -> 0.49084231
A20: Ozone formation, Human health | B20: kg NOx eq | C20: 0.0016173203 | D20: 0 | E20: 8.6852126e-05 | F20: 0.00020740962 | G20: 0.001070373 | H20: 8.8834354e-05 | I20: 0.00016385123 | J20: =SUM(D20:G20,I20) -> 0.001528486
A21: Fine particulate matter formation | B21: kg PM2.5 eq | C21: 0.00071476988 | D21: 0 | E21: 6.0798478e-05 | F21: 5.7399881e-05 | G21: 0.00045115551 | H21: 5.927142e-05 | I21: 8.6144591e-05 | J21: =SUM(D21:G21,I21) -> 0.00065549846
A22: Ozone formation, Terrestrial ecosystems | B22: kg NOx eq | C22: 0.0017157994 | D22: 0 | E22: 8.90953e-05 | F22: 0.00023602442 | G22: 0.0011286693 | H22: 9.2582774e-05 | I22: 0.00016942761 | J22: =SUM(D22:G22,I22) -> 0.0016232166
A23: Terrestrial acidification | B23: kg SO2 eq | C23: 0.0021370205 | D23: 0 | E23: 0.00014072779 | F23: 0.00014365068 | G23: 0.0012537697 | H23: 9.1328081e-05 | I23: 0.00050754429 | J23: =SUM(D23:G23,I23) -> 0.0020456925
A24: Freshwater eutrophication | B24: kg P eq | C24: 0.00047038479 | D24: 0.00032 | E24: 1.8059822e-05 | F24: 1.0717983e-05 | G24: 8.4901439e-05 | H24: 2.7142166e-05 | I24: 9.563378e-06 | J24: =SUM(D24:G24,I24) -> 0.00044324262 | K24: =J24/'Final normalization scores No I'!$D$23 -> 0.00068202887 | L24: FEU
A25: Marine eutrophication | B25: kg N eq | C25: 0.0011934581 | D25: 0.00093852 | E25: 8.91378e-07 | F25: 3.299979e-06 | G25: 1.4448685e-05 | H25: 3.171538e-06 | I25: 0.0002331265 | J25: =SUM(D25:G25,I25) -> 0.0011902865 | K25: =J25/'Final normalization scores No I'!$D$29 -> 0.00025776133 | L25: MEU
A26: Terrestrial ecotoxicity | B26: kg 1,4-DCB | C26: 1.4390453 | D26: 0 | E26: 0.078929432 | F26: 0.1142321 | G26: 0.70545153 | H26: 0.18080687 | I26: 0.35962539 | J26: =SUM(D26:G26,I26) -> 1.2582385 | K26: =J26/'Final normalization scores No I'!$D$17 -> 8.2777154e-05 | L26: TET
A27: Freshwater ecotoxicity | B27: kg 1,4-DCB | C27: 0.030882962 | D27: 0 | E27: 0.0031681787 | F27: 0.0018864703 | G27: 0.020457462 | H27: 0.0041049913 | I27: 0.0012658596 | J27: =SUM(D27:G27,I27) -> 0.026777971 | K27: =J27/'Final normalization scores No I'!$D$24 -> 0.0010636856 | L27: FET
A28: Marine ecotoxicity | B28: kg 1,4-DCB | C28: 0.040405524 | D28: 0 | E28: 0.0043537193 | F28: 0.0026558762 | G28: 0.02612985 | H28: 0.0054928593 | I28: 0.0017732197 | J28: =SUM(D28:G28,I28) -> 0.034912665 | K28: =J28/'Final normalization scores No I'!$D$28 -> 0.00080364598 | L28: MET
A29: Human carcinogenic toxicity | B29: kg 1,4-DCB | C29: 0.19059242 | D29: 0 | E29: 0.054252302 | F29: 0.015589148 | G29: 0.075001785 | H29: 0.040845109 | I29: 0.0049040745 | J29: =SUM(D29:G29,I29) -> 0.14974731
A30: Human non-carcinogenic toxicity | B30: kg 1,4-DCB | C30: 3.001244 | D30: 0 | E30: 0.070501686 | F30: 0.040477678 | G30: 0.36510427 | H30: 0.11486248 | I30: 2.4102979 | J30: =SUM(D30:G30,I30) -> 2.8863815 | K30: =J30/'Final normalization scores No I'!$D$10 -> 9.2358764e-05
A31: Land use | B31: m2a crop eq | C31: 0.023974587 | D31: 0 | E31: 0.00072541488 | F31: 0.0014955503 | G31: 0.019199669 | H31: 0.0012385742 | I31: 0.0013153786 | J31: =SUM(D31:G31,I31) -> 0.022736013
A32: Mineral resource scarcity | B32: kg Cu eq | C32: 0.0034921377 | D32: 0 | E32: 0.0011149343 | F32: 0.00024077531 | G32: 0.0015188264 | H32: 0.00054579483 | I32: 7.1806849e-05 | J32: =SUM(D32:G32,I32) -> 0.0029463429
A33: Fossil resource scarcity | B33: kg oil eq | C33: 0.28314193 | D33: 0 | E33: 0.007583206 | F33: 0.11544674 | G33: 0.14355795 | H33: 0.0089324224 | I33: 0.0076216134 | J33: =SUM(D33:G33,I33) -> 0.27420951
A34: Water consumption | B34: m3 | C34: -0.25284788 | D34: 0 | E34: 0.0002058941 | F34: 0.00035695661 | G34: 0.0067475702 | H34: -0.25965404 | I34: -0.00050425733 | J34: =SUM(D34:G34,I34) -> 0.0068061636 | K34: =J34/'Final normalization scores No I'!$D$25 -> 2.5525737e-05 | L34: WU
B38: Normalized impacts
B39: =K17 -> 0.0001561636 | C39: GWP
B40: =K24 -> 0.00068202887 | C40: FEU
B41: =K25 -> 0.00025776133 | C41: MEU
B42: =K26 -> 8.2777154e-05 | C42: TET
B43: =K27 -> 0.0010636856 | C43: FET
B44: =K28 -> 0.00080364598 | C44: MET
B45: =K34 -> 2.5525737e-05 | C45: WU

Sheet Vedra_1kgPO4eq_ReCiPe
A1: SimaPro 10.3.0.1 | C1: Date: | D1: 46227 | E1: Time: | F1: 0.45729021
A2: Project | B2: Alberto Fraile
A5: Calculation: | B5: Analyze
A6: Results: | B6: Impact assessment
A7: Product: | B7: 1 kg Vedra_1kgPO4-eq (of project Alberto Fraile)
A8: Method: | B8: ReCiPe 2016 Midpoint (H) V1.12 / World (2010) H
A9: Indicator: | B9: Characterization
A10: Skip categories: | B10: Never
A11: Exclude infrastructure processes: | B11: No
A12: Exclude long-term emissions: | B12: No
A13: Sorted on item: | B13: Impact category
A14: Sort order: | B14: Ascending
A16: Impact category | B16: Unit | C16: Total | D16: Vedra_1kgPO4-eq | E16: Polyaluminium chloride {GLO}| market for polyaluminium chloride | Cut-off, U | F16: Methanol {RER}| market for methanol | Cut-off, U | G16: Electricity, medium voltage {ES}| market for electricity, medium voltage | Cut-off, U | H16: Wastewater, unpolluted {RoW}| market for wastewater, unpolluted | Cut-off, U | I16: Sewage sludge, 97% water, WWT-SLF, municipal solid waste {ES}| market for sewage sludge, 97% water, WWT-SLF, municipal solid waste | Cut-off, U | J16: Total w/o wastewater | K16: Normalization
A17: Global warming | B17: kg CO2 eq | C17: 42.53725 | D17: 17.438 | E17: 0.97341027 | F17: 3.9185215 | G17: 15.832397 | H17: 1.2093012 | I17: 3.1656202 | J17: =SUM(D17:G17,I17) -> 41.327949 | K17: =J17/'Final normalization scores No I'!$D$4 -> 0.0051721953 | L17: GWP
A18: Stratospheric ozone depletion | B18: kg CFC11 eq | C18: 0.00017812621 | D18: 0.000132 | E18: 3.97006e-07 | F18: 8.24525e-07 | G18: 9.33978e-06 | H18: 2.62273e-07 | I18: 3.5302626e-05 | J18: =SUM(D18:G18,I18) -> 0.00017786394
A19: Ionizing radiation | B19: kBq Co-60 eq | C19: 16.331961 | D19: 0 | E19: 0.049343164 | F19: 0.11430423 | G19: 16.106944 | H19: 0.049037003 | I19: 0.012332082 | J19: =SUM(D19:G19,I19) -> 16.282923
A20: Ozone formation, Human health | B20: kg NOx eq | C20: 0.05364887 | D20: 0 | E20: 0.0028661201 | F20: 0.0068807317 | G20: 0.03550846 | H20: 0.0029486172 | I20: 0.0054449412 | J20: =SUM(D20:G20,I20) -> 0.050700253
A21: Fine particulate matter formation | B21: kg PM2.5 eq | C21: 0.023707188 | D21: 0 | E21: 0.0020063498 | F21: 0.0019042183 | G21: 0.014966594 | H21: 0.0019673552 | I21: 0.0028626714 | J21: =SUM(D21:G21,I21) -> 0.021739833
A22: Ozone formation, Terrestrial ecosystems | B22: kg NOx eq | C22: 0.056915825 | D22: 0 | E22: 0.0029401449 | F22: 0.0078300163 | G22: 0.037442379 | H22: 0.0030730359 | I22: 0.0056302497 | J22: =SUM(D22:G22,I22) -> 0.05384279
A23: Terrestrial acidification | B23: kg SO2 eq | C23: 0.070899615 | D23: 0 | E23: 0.004644017 | F23: 0.0047655544 | G23: 0.041592447 | H23: 0.0030313898 | I23: 0.016866207 | J23: =SUM(D23:G23,I23) -> 0.067868225
A24: Freshwater eutrophication | B24: kg P eq | C24: 0.015726764 | D24: 0.01074 | E24: 0.00059597413 | F24: 0.00035556484 | G24: 0.002816513 | H24: 0.00090091112 | I24: 0.00031780066 | J24: =SUM(D24:G24,I24) -> 0.014825853 | K24: =J24/'Final normalization scores No I'!$D$23 -> 0.022812922 | L24: FEU
A25: Marine eutrophication | B25: kg N eq | C25: 0.039596109 | D25: 0.0311256 | E25: 2.941547e-05 | F25: 0.00010947548 | G25: 0.00047931941 | H25: 0.00010527067 | I25: 0.007747028 | J25: =SUM(D25:G25,I25) -> 0.039490838 | K25: =J25/'Final normalization scores No I'!$D$29 -> 0.0085518996 | L25: MEU
A26: Terrestrial ecotoxicity | B26: kg 1,4-DCB | C26: 47.748974 | D26: 0 | E26: 2.6046712 | F26: 3.7896044 | G26: 23.402588 | H26: 6.0013972 | I26: 11.950713 | J26: =SUM(D26:G26,I26) -> 41.747577 | K26: =J26/'Final normalization scores No I'!$D$17 -> 0.002746495 | L26: TET
A27: Freshwater ecotoxicity | B27: kg 1,4-DCB | C27: 1.0241068 | D27: 0 | E27: 0.1045499 | F27: 0.062582905 | G27: 0.67865408 | H27: 0.13625413 | I27: 0.042065788 | J27: =SUM(D27:G27,I27) -> 0.88785267 | K27: =J27/'Final normalization scores No I'!$D$24 -> 0.035267652 | L27: FET
A28: Marine ecotoxicity | B28: kg 1,4-DCB | C28: 1.3398563 | D28: 0 | E28: 0.14367274 | F28: 0.088107638 | G28: 0.86682936 | H28: 0.18232067 | I28: 0.058925873 | J28: =SUM(D28:G28,I28) -> 1.1575356 | K28: =J28/'Final normalization scores No I'!$D$28 -> 0.026645025 | L28: MET
A29: Human carcinogenic toxicity | B29: kg 1,4-DCB | C29: 6.3143032 | D29: 0 | E29: 1.790326 | F29: 0.51716381 | G29: 2.4881027 | H29: 1.3557434 | I29: 0.16296733 | J29: =SUM(D29:G29,I29) -> 4.9585598
A30: Human non-carcinogenic toxicity | B30: kg 1,4-DCB | C30: 99.690498 | D30: 0 | E30: 2.3265556 | F30: 1.3428309 | G30: 12.111937 | H30: 3.8125509 | I30: 80.096623 | J30: =SUM(D30:G30,I30) -> 95.877946 | K30: =J30/'Final normalization scores No I'!$D$10 -> 0.0030679134
A31: Land use | B31: m2a crop eq | C31: 0.79530362 | D31: 0 | E31: 0.023938691 | F31: 0.049614287 | G31: 0.63692815 | H31: 0.041111137 | I31: 0.043711352 | J31: =SUM(D31:G31,I31) -> 0.75419248
A32: Mineral resource scarcity | B32: kg Cu eq | C32: 0.11566828 | D32: 0 | E32: 0.036792831 | F32: 0.0079876253 | G32: 0.050385416 | H32: 0.01811619 | I32: 0.0023862138 | J32: =SUM(D32:G32,I32) -> 0.097552086
A33: Fossil resource scarcity | B33: kg oil eq | C33: 9.3922862 | D33: 0 | E33: 0.2502458 | F33: 3.8298999 | G33: 4.7623789 | H33: 0.29648771 | I33: 0.25327388 | J33: =SUM(D33:G33,I33) -> 9.0957985
A34: Water consumption | B34: m3 | C34: -8.3927941 | D34: 0 | E34: 0.0067945054 | F34: 0.011841894 | G34: 0.22384331 | H34: -8.6185168 | I34: -0.016756978 | J34: =SUM(D34:G34,I34) -> 0.22572273 | K34: =J34/'Final normalization scores No I'!$D$25 -> 0.00084654724 | L34: WU
B38: Normalized impacts
B39: =K17 -> 0.0051721953 | C39: GWP
B40: =K24 -> 0.022812922 | C40: FEU
B41: =K25 -> 0.0085518996 | C41: MEU
B42: =K26 -> 0.002746495 | C42: TET
B43: =K27 -> 0.035267652 | C43: FET
B44: =K28 -> 0.026645025 | C44: MET
B45: =K34 -> 0.00084654724 | C45: WU

Sheet Final normalization scores No I
B1: Midpoint | G1: Endpoint
B2: unit | C2: World | G2: unit | H2: World
A3: Human health | C3: Individualistic | D3: Hierarchic | E3: Egalitarian | H3: Individualistic | I3: Hierarchic | J3: Egalitarian
A4: Global Warming - Human health | B4: kg CO2 eq. per person in 2010 | C4: 10757.059 | D4: 7990.4077 | E4: 5797.6041 | G4: DALY per person in 2010 | H4: 0.00087347319 | I4: 0.0074150983 | J4: 0.072470051
A5: Stratospheric ozone depletion - Human health | B5: kg CFC11 eq. per person in 2010 | C5: 0.065329392 | D5: 0.060010005 | E5: 0.070437281 | G5: DALY per person in 2010 | H5: 1.5483066e-05 | I5: 3.1865313e-05 | J5: 9.4385956e-05
A6: Ionzing Radiation - Human health | B6: kBq Co-60 emitted to air eq. per person in 2010 | C6: 469.71621 | D6: 479.91735 | E6: 698.58082 | G6: DALY per person in 2010 | H6: 3.1940702e-06 | I6: 4.0792975e-06 | J6: 9.7801315e-06
A7: Fine particulate matter formation - Human health | B7: kg PM2.5 eq. per person in 2010 | C7: 16.020088 | D7: 25.569595 | E7: 25.569595 | G7: DALY per person in 2010 | H7: 0.010009245 | I7: 0.01609484 | J7: 0.01609484
A8: Photochemical ozone formation - Human health | B8: kg NOx eq. per person in 2010 | C8: 20.567457 | D8: 20.567457 | E8: 20.567457 | G8: DALY per person in 2010 | H8: 1.8022734e-05 | I8: 1.8022734e-05 | J8: 1.8022734e-05
A9: Toxicity - Human health (cancer) | B9: kg 1,4-DCB emitted to urban air eq. per person in 2010 | C9: 0.99033506 | D9: 10.298306 | E9: 295.23401 | G9: DALY per person in 2010 | H9: 3.2879124e-06 | I9: 3.4190377e-05 | J9: 0.00098017692
A10: Toxicity - Human health (non-cancer) | B10: kg 1,4-DCB emitted to urban air eq. per person in 2010 | C10: 50.949702 | D10: 31251.842 | E10: 2224349.2 | G10: DALY per person in 2010 | H10: 3.3881552e-07 | I10: 0.00020782475 | J10: 0.014791922
A11: Water consumption - human health | B11: m3 consumed per person in 2010 | C11: 266.63926 | D11: 266.63926 | E11: 266.63926 | G11: DALY per person in 2010 | H11: 0.00019602787 | I11: 0.00019602787 | J11: 0.00029066799
A13: Terrestrial ecosystems
A14: Global Warming - Terrestrial ecosystems | B14: kg CO2 eq. per person in 2010 | C14: 10757.059 | D14: 7990.4077 | E14: 5797.6041 | G14: Species.year per person in 2010 | H14: 5.7227554e-06 | I14: 2.2373141e-05 | J14: 0.0001449401
A15: Photochemical ozone formation - Terrestrial ecosystems | B15: kg NOx eq. per person in 2010 | C15: 17.749328 | D15: 17.749328 | E15: 17.749328 | G15: Species.year per person in 2010 | H15: 2.2387618e-06 | I15: 2.2387618e-06 | J15: 2.2387618e-06
A16: Acidification - Terrestrial ecosystems | B16: kg SO2 eq. per person in 2010 | C16: 40.980515 | D16: 40.980515 | E16: 40.980515 | G16: Species.year per person in 2010 | H16: 8.4198919e-06 | I16: 8.4198919e-06 | J16: 8.4198919e-06
A17: Toxicity - Terrestrial ecosystems | B17: kg 1,4-DBC emitted to industrial soil eq. per person in 2010 | C17: 6727.901 | D17: 15200.311 | E17: 16364.046 | G17: Species.year per person in 2010 | H17: 0.00036242014 | I17: 0.00081881388 | J17: 0.00088150227
A18: Water consumption - terrestrial ecosystems | B18: m3 consumed per person in 2010 | C18: 266.63926 | D18: 266.63926 | E18: 266.63926 | G18: Species.year per person in 2010 | H18: 0 | I18: 3.484367e-06 | J18: 3.484367e-06
A19: Land use - occupation | B19: m2∙annual crop eq per person in 2010 | C19: 6167.4823 | D19: 6167.4823 | E19: 6167.4823 | G19: Species.year per person in 2010 | H19: 0.00062336286 | I19: 0.00062336286 | J19: 0.00062336286
A21: Freshwater ecosystems
A22: Global Warming - Freshwater ecosystems | B22: kg CO2 eq. per person in 2010 | C22: 10757.059 | D22: 7990.4077 | E22: 5797.6041 | G22: Species.year per person in 2010 | H22: 1.5597735e-10 | I22: 6.1126619e-10 | J22: 3.953966e-09
A23: Eutrophication - Freshwater ecosystems | B23: kg P to freshwater eq. per person in 2010 | C23: 0.64988836 | D23: 0.64988836 | E23: 0.64988836 | G23: Species.year per person in 2010 | H23: 4.8963522e-07 | I23: 4.8963522e-07 | J23: 4.8963522e-07
A24: Toxicity - Freshwater ecosystems | B24: kg 1,4-DBC emitted to freshwater eq. per person in 2010 | C24: 12.570526 | D24: 25.174703 | E24: 290.34738 | G24: Species.year per person in 2010 | H24: 8.7365157e-09 | I24: 1.7496419e-08 | J24: 2.0179143e-07
A25: Water consumption -aquatic ecosystems | B25: m3 consumed per person in 2010 | C25: 266.63926 | D25: 266.63926 | E25: 266.63926 | G25: Species.year per person in 2010 | H25: 6.157106e-10 | I25: 6.157106e-10 | J25: 6.157106e-10
A27: Marine ecosystems
A28: Toxicity - Marine ecosystems | B28: kg 1,4-DBC emitted to sea water eq. per person in 2010 | C28: 8.7973954 | D28: 43.442842 | E28: 2463104.9 | G28: Species.year per person in 2010 | H28: 9.2372652e-10 | I28: 4.5614984e-09 | J28: 0.00025862601
A29: Eutrophication - marine ecosystems | B29: kg N to marine water equivalents per person in 2010 | C29: 4.6177856 | D29: 4.6177856 | E29: 4.6177856 | G29: Species.year per person in 2011 | H29: 6.1234351e-09 | I29: 6.1234351e-09 | J29: 6.1234351e-09
A31: Resources
A32: Mineral resource scarcity | B32: kg Cu-eq per person in 2010 | C32: 193174.21 | D32: 120051.21 | E32: 120051.21 | G32: USD2013 per person in 2010 | H32: 30799.372 | I32: 27741.958 | J32: 27741.958
A33: Fossil resource scarcity | G33: USD2013 per person in 2010 | H33: 291.35214 | I33: 291.35214 | J33: 291.35214
A34: Crude oil | B34: oil-eq per person in 2010 | C34: 569.90476 | D34: 569.90476 | E34: 569.90476
A35: Natural gas | B35: oil-eq per person in 2010 | C35: 0.40197863 | D35: 0.40197863 | E35: 0.40197863
A36: Hard coal | B36: oil-eq per person in 2010 | C36: 381.51426 | D36: 381.51426 | E36: 381.51426
A37: Brown coal | B37: oil-eq per person in 2010 | C37: 31.456423 | D37: 31.456423 | E37: 31.456423
A38: Peat | B38: oil-eq per person in 2010
A42: World population
A43: 6895889018

Sheet Evaluación de Impactos
B4: Normalized impacts
C5: C hab eq | D5: C kg PO4 eq | E5: V hab eq | F5: V kg PO4 eq
B6: GWP | C6: =Cerceda_1habeq_ReCiPe!B39 -> 0.00052493078 | D6: =Cerceda_1kgPO4eq_ReCiPe!B39 -> 0.062457038 | E6: =Vedra_1habeq_ReCiPe!B39 -> 0.0001561636 | F6: =Vedra_1kgPO4eq_ReCiPe!B39 -> 0.0051721953
B7: FEU | C7: =Cerceda_1habeq_ReCiPe!B40 -> 0.01425504 | D7: =Cerceda_1kgPO4eq_ReCiPe!B40 -> 1.7147386 | E7: =Vedra_1habeq_ReCiPe!B40 -> 0.00068202887 | F7: =Vedra_1kgPO4eq_ReCiPe!B40 -> 0.022812922
B8: MEU | C8: =Cerceda_1habeq_ReCiPe!B41 -> 0.0020665211 | D8: =Cerceda_1kgPO4eq_ReCiPe!B41 -> 0.24869882 | E8: =Vedra_1habeq_ReCiPe!B41 -> 0.00025776133 | F8: =Vedra_1kgPO4eq_ReCiPe!B41 -> 0.0085518996
B9: TET | C9: =Cerceda_1habeq_ReCiPe!B42 -> 0.00016047439 | D9: =Cerceda_1kgPO4eq_ReCiPe!B42 -> 0.019311179 | E9: =Vedra_1habeq_ReCiPe!B42 -> 8.2777154e-05 | F9: =Vedra_1kgPO4eq_ReCiPe!B42 -> 0.002746495
B10: FET | C10: =Cerceda_1habeq_ReCiPe!B43 -> 0.10095001 | D10: =Cerceda_1kgPO4eq_ReCiPe!B43 -> 12.147101 | E10: =Vedra_1habeq_ReCiPe!B43 -> 0.0010636856 | F10: =Vedra_1kgPO4eq_ReCiPe!B43 -> 0.035267652
B11: MET | C11: =Cerceda_1habeq_ReCiPe!B44 -> 0.074335649 | D11: =Cerceda_1kgPO4eq_ReCiPe!B44 -> 8.9446511 | E11: =Vedra_1habeq_ReCiPe!B44 -> 0.00080364598 | F11: =Vedra_1kgPO4eq_ReCiPe!B44 -> 0.026645025
B12: WU | C12: =Cerceda_1habeq_ReCiPe!B45 -> -4.281442e-06 | D12: =Cerceda_1kgPO4eq_ReCiPe!B45 -> -0.00051452007 | E12: =Vedra_1habeq_ReCiPe!B45 -> 2.5525737e-05 | F12: =Vedra_1kgPO4eq_ReCiPe!B45 -> 0.00084654724
B14: =B4 -> Normalized impacts
C15: Cerceda | D15: Vedra
B16: =B6 -> GWP | C16: =C6 -> 0.00052493078 | D16: =E6 -> 0.0001561636
B17: =B7 -> FEU | C17: =C7 -> 0.01425504 | D17: =E7 -> 0.00068202887
B18: =B8 -> MEU | C18: =C8 -> 0.0020665211 | D18: =E8 -> 0.00025776133
B19: =B9 -> TET | C19: =C9 -> 0.00016047439 | D19: =E9 -> 8.2777154e-05
B20: =B10 -> FET | C20: =C10 -> 0.10095001 | D20: =E10 -> 0.0010636856
B21: =B11 -> MET | C21: =C11 -> 0.074335649 | D21: =E11 -> 0.00080364598
B23: =B14 -> Normalized impacts
C24: =C15 -> Cerceda | D24: =D15 -> Vedra
B25: =B16 -> GWP | C25: =C16/$C$20 -> 0.0051999079 | D25: =D16/MAX($D$16:$D$21) -> 0.14681368
B26: =B17 -> FEU | C26: =C17/$C$20 -> 0.1412089 | D26: =D17/MAX($D$16:$D$21) -> 0.64119401
B27: =B18 -> MEU | C27: =C18/$C$20 -> 0.020470736 | D27: =D18/MAX($D$16:$D$21) -> 0.24232848
B28: =B19 -> TET | C28: =C19/$C$20 -> 0.0015896421 | D28: =D19/MAX($D$16:$D$21) -> 0.077821069
B29: =B20 -> FET | C29: =C20/$C$20 -> 1 | D29: =D20/MAX($D$16:$D$21) -> 1
B30: =B21 -> MET | C30: =C21/$C$20 -> 0.73636096 | D30: =D21/MAX($D$16:$D$21) -> 0.75552959
B35: Category | C35: Cerceda | D35: Vedra
B36: GWP | C36: =C25 -> 0.0051999079 | D36: =D25 -> 0.14681368
B37: FEU | C37: =C26 -> 0.1412089 | D37: =D26 -> 0.64119401
B38: MEU | C38: =C27 -> 0.020470736 | D38: =D27 -> 0.24232848
B39: TET | C39: =C28 -> 0.0015896421 | D39: =D28 -> 0.077821069
B40: FET | C40: =C29 -> 1 | D40: =D29 -> 1
B41: MET | C41: =C30 -> 0.73636096 | D41: =D30 -> 0.75552959
B153: logaritmización!
C154: C hab eq | D154: C kg PO4 eq | E154: V hab eq | F154: V kg PO4 eq
B155: GWP | C155: =-LOG(C6) -> 3.279898 | D155: =-LOG(D6) -> 1.2044186 | E155: =-LOG(E6) -> 3.8064202 | F155: =-LOG(F6) -> 2.2863251
B156: FEU | C156: =-LOG(C7) -> 1.8460315 | D156: =-LOG(D7) -> -0.23419792 | E156: =-LOG(E7) -> 3.1661972 | F156: =-LOG(F7) -> 1.6418191
B157: MEU | C157: =-LOG(C8) -> 2.6847602 | D157: =-LOG(D8) -> 0.60432628 | E157: =-LOG(E8) -> 3.5887822 | F157: =-LOG(F8) -> 2.0679374
B158: TET | C158: =-LOG(C9) -> 3.7945943 | D158: =-LOG(D9) -> 1.7141912 | E158: =-LOG(E9) -> 4.0820895 | F158: =-LOG(F9) -> 2.5612212
B159: FET | C159: =-LOG(C10) -> 0.99589362 | D159: =-LOG(D10) -> -1.0844727 | E159: =-LOG(E10) -> 2.9731867 | F159: =-LOG(F10) -> 1.4526235
B160: MET | C160: =-LOG(C11) -> 1.1288029 | D160: =-LOG(D11) -> -0.9515634 | E160: =-LOG(E11) -> 3.0949352 | F160: =-LOG(F11) -> 1.5743839
...
